<?xml version="1.0" ?>
<!-- =================================================================================== -->
<!-- |    This document was autogenerated by xacro from mrm.xacro                      | -->
<!-- |    EDITING THIS FILE BY HAND IS NOT RECOMMENDED                                 | -->
<!-- =================================================================================== -->
<robot name="mrm">
  <link name="base_link">
    <visual>
      <origin rpy="0 0 0" xyz="0 0 0"/>
      <geometry>
        <cylinder length="0.042" radius="0.048"/>
      </geometry>
    </visual>
  </link>
  <joint name="base_link__link_01" type="revolute">
    <axis xyz="0 0 1"/>
    <limit effort="1000.0" lower="-1.57" upper="1.57" velocity="0.1"/>
    <origin rpy="0 0 0" xyz="0 0 0.021"/>
    <parent link="base_link"/>
    <child link="link_01"/>
  </joint>
  <link name="link_01">
    <visual>
      <origin rpy="0 0 0" xyz="0 0 0.0228"/>
      <geometry>
        <cylinder length="0.0456" radius="0.021"/>
      </geometry>
    </visual>
  </link>
  <joint name="link_01__link_02" type="revolute">
    <axis xyz="0 1 0"/>
    <limit effort="1000.0" lower="-1.57" upper="1.57" velocity="0.1"/>
    <origin rpy="0 0 0" xyz="0 0 0.0456"/>
    <parent link="link_01"/>
    <child link="link_02"/>
  </joint>
  <link name="link_02">
    <visual>
      <origin rpy="0 0 0" xyz="0 0 0.06625"/>
      <geometry>
        <cylinder length="0.1325" radius="0.021"/>
      </geometry>
    </visual>
  </link>
  <joint name="link_02__link_03" type="revolute">
    <axis xyz="0 1 0"/>
    <limit effort="1000.0" lower="-1.57" upper="1.57" velocity="0.1"/>
    <origin rpy="0 0 0" xyz="0 0 0.1325"/>
    <parent link="link_02"/>
    <child link="link_03"/>
  </joint>
  <link name="link_03">
    <visual>
      <origin rpy="0 0 0" xyz="0 0 0.04175"/>
      <geometry>
        <cylinder length="0.0835" radius="0.021"/>
      </geometry>
    </visual>
  </link>
  <joint name="link_03__link_04" type="revolute">
    <axis xyz="0 0 1"/>
    <limit effort="1000.0" lower="-1.57" upper="1.57" velocity="0.1"/>
    <origin rpy="0 0 0" xyz="0 0 0.0835"/>
    <parent link="link_03"/>
    <child link="link_04"/>
  </joint>
  <link name="link_04">
    <visual>
      <origin rpy="0 0 0" xyz="0 0 0.0245"/>
      <geometry>
        <cylinder length="0.049" radius="0.021"/>
      </geometry>
    </visual>
  </link>
  <joint name="link_04__end_effector" type="revolute">
    <axis xyz="0 1 0"/>
    <limit effort="1000.0" lower="-1.57" upper="1.57" velocity="0.1"/>
    <origin rpy="0 0 0" xyz="0 0 0.049"/>
    <parent link="link_04"/>
    <child link="end_effector"/>
  </joint>
  <link name="end_effector">
    <visual>
      <origin rpy="0 0 0" xyz="0 0 0.059"/>
      <geometry>
        <cylinder length="0.118" radius="0.021"/>
      </geometry>
    </visual>
  </link>
</robot>

